<?xml version="1.0" encoding="utf-8" ?>
<!-- =================================================================================== -->
<!-- |    This document was autogenerated by xacro from /home/hayashi/worksp/yaskawa/src/motoman_project/motoman_description/robots/sia5/sia5_twintool.urdf.xacro | -->
<!-- |    EDITING THIS FILE BY HAND IS NOT RECOMMENDED                                 | -->
<!-- =================================================================================== -->
<robot name="sia5">
    <material name="black">
        <color rgba="0.0 0.0 0.0 1.0" />
    </material>
    <material name="blue">
        <color rgba="0.0 0.0 0.8 1.0" />
    </material>
    <material name="green">
        <color rgba="0.0 0.8 0.0 1.0" />
    </material>
    <material name="grey">
        <color rgba="0.2 0.2 0.2 1.0" />
    </material>
    <material name="orange">
        <color rgba="1.0 0.423529411765 0.0392156862745 1.0" />
    </material>
    <material name="brown">
        <color rgba="0.870588235294 0.811764705882 0.764705882353 1.0" />
    </material>
    <material name="red">
        <color rgba="0.8 0.0 0.0 1.0" />
    </material>
    <material name="white">
        <color rgba="1.0 1.0 1.0 1.0" />
    </material>
    <link name="base_link">
        <visual>
            <geometry>
                <mesh filename="package://motoman_description/meshes/sia5/visual/COLLADA/base_link.dae" />
            </geometry>
        </visual>
        <collision>
            <geometry>
                <mesh filename="package://motoman_description/meshes/sia5/collision/STL/base_link.stl" />
            </geometry>
        </collision>
        
<inertial>
            <origin rpy="0 0 0" xyz="-0.025918 -0.000376 0.076105" />
            <mass value="9.23913043478" />
            <inertia ixx="0.0378685009058" ixy="0" ixz="0" iyy="0.0465867830616" iyz="0" izz="0.0514065294384" />
        </inertial>

    </link>
    <link name="link_s">
        <visual>
            <geometry>
                <mesh filename="package://motoman_description/meshes/sia5/visual/COLLADA/link_s.dae" />
            </geometry>
        </visual>
        <collision>
            <geometry>
                <mesh filename="package://motoman_description/meshes/sia5/collision/STL/link_s.stl" />
            </geometry>
        </collision>
        
<inertial>
            <origin rpy="0 0 0" xyz="0 0 0" />
            <mass value="8.36956521739" />
            <inertia ixx="0.1285284" ixy="0" ixz="0" iyy="0.127697251957" iyz="0" izz="0.0186623672464" />
        </inertial>

    </link>
    <link name="link_l">
        <visual>
            <geometry>
                <mesh filename="package://motoman_description/meshes/sia5/visual/COLLADA/link_l.dae" />
            </geometry>
        </visual>
        <collision>
            <geometry>
                <mesh filename="package://motoman_description/meshes/sia5/collision/STL/link_l.stl" />
            </geometry>
        </collision>
        
<inertial>
            <origin rpy="3.14159274 0 0" xyz="0 -0.006 0.15" />
            <mass value="7.60869565217" />
            <inertia ixx="0.12248884058" ixy="0" ixz="0" iyy="0.117554616667" iyz="0" izz="0.0177495804348" />
        </inertial>

    </link>
    <link name="link_e">
        <visual>
            <geometry>
                <mesh filename="package://motoman_description/meshes/sia5/visual/COLLADA/link_e.dae" />
            </geometry>
        </visual>
        <collision>
            <geometry>
                <mesh filename="package://motoman_description/meshes/sia5/collision/STL/link_e.stl" />
            </geometry>
        </collision>
        
<inertial>
            <origin rpy="0 0 -1.57079637" xyz="0 0 0" />
            <mass value="1.30434782609" />
            <inertia ixx="0.0122899381739" ixy="0" ixz="0" iyy="0.0117127787826" iyz="0" izz="0.00344401234783" />
        </inertial>

    </link>
    <link name="link_u">
        <visual>
            <geometry>
                <mesh filename="package://motoman_description/meshes/sia5/visual/COLLADA/link_u.dae" />
            </geometry>
        </visual>
        <collision>
            <geometry>
                <mesh filename="package://motoman_description/meshes/sia5/collision/STL/link_u.stl" />
            </geometry>
        </collision>
        
<inertial>
            <origin rpy="-3.14159274 1.57079637 0" xyz="0.008 -0.06 -0.131" />
            <mass value="1.08695652174" />
            <inertia ixx="0.0110207115768" ixy="0" ixz="0" iyy="0.00996803594203" iyz="0" izz="0.00214043853333" />
        </inertial>

    </link>
    <link name="link_r">
        <visual>
            <geometry>
                <mesh filename="package://motoman_description/meshes/sia5/visual/COLLADA/link_r.dae" />
            </geometry>
        </visual>
        <collision>
            <geometry>
                <mesh filename="package://motoman_description/meshes/sia5/collision/STL/link_r.stl" />
            </geometry>
        </collision>
        
<inertial>
            <origin rpy="0 0 -1.57079637" xyz="0 0 0" />
            <mass value="0.978260869565" />
            <inertia ixx="0.0108400832201" ixy="0" ixz="0" iyy="0.010708873981" iyz="0" izz="0.00140456861413" />
        </inertial>

    </link>
    <link name="link_b">
        <visual>
            <geometry>
                <mesh filename="package://motoman_description/meshes/sia5/visual/COLLADA/link_b.dae" />
            </geometry>
        </visual>
        <collision>
            <geometry>
                <mesh filename="package://motoman_description/meshes/sia5/collision/STL/link_b.stl" />
            </geometry>
        </collision>
        
<inertial>
            <origin rpy="1.57079637 -1.57079637 0" xyz="0 0.0045 0.1365" />
            <mass value="0.869565217391" />
            <inertia ixx="0.00814341869565" ixy="0" ixz="0" iyy="0.00709473869565" iyz="0" izz="0.000736577391304" />
        </inertial>

    </link>
    <link name="link_t">
        <visual>
            <geometry>
                <mesh filename="package://motoman_description/meshes/sia5/visual/COLLADA/link_t.dae" />
            </geometry>
        </visual>
        <collision>
            <geometry>
                <mesh filename="package://motoman_description/meshes/sia5/collision/STL/link_t.stl" />
            </geometry>
        </collision>
        
<inertial>
            <mass value="0.54347826087" />
            <inertia ixx="0.003" ixy="0" ixz="0" iyy="0.003" iyz="0" izz="0.001" />
        </inertial>

    </link>
    <link name="tool0" />
    <joint name="joint_s" type="revolute">
        <origin rpy="0 0 0" xyz="0 0 0.1765" />
        <parent link="base_link" />
        <child link="link_s" />
        <axis xyz="0 0 1" />
        <dynamics damping="0.7" friction="0.7" />
        <limit effort="30.0" lower="-2.98451293719" upper="2.98451293719" velocity="3.31612567" />
    </joint>
    <joint name="joint_l" type="revolute">
        <origin rpy="0 0 0" xyz="0 0.006 0.136" />
        <parent link="link_s" />
        <child link="link_l" />
        <axis xyz="0 1 0" />
        <dynamics damping="0.7" friction="0.7" />
        <limit effort="30.0" lower="-1.8238691185" upper="1.8238691185" velocity="3.31612567" />
    </joint>
    <joint name="joint_e" type="revolute">
        <origin rpy="0 0 0" xyz="0 -0.006 0.15" />
        <parent link="link_l" />
        <child link="link_e" />
        <axis xyz="0 0 1" />
        <dynamics damping="0.7" friction="0.7" />
        <limit effort="30.0" lower="-2.8187068195" upper="2.8187068195" velocity="3.31612567" />
    </joint>
    <joint name="joint_u" type="revolute">
        <origin rpy="1.57079637 0 0" xyz="0.085 -0.00826931 0.12275299" />
        <parent link="link_e" />
        <child link="link_u" />
        <axis xyz="0 0 1" />
        <dynamics damping="0.7" friction="0.7" />
        <limit effort="30.0" lower="-1.4922565515" upper="1.90677226025" velocity="3.31612567" />
    </joint>
    <joint name="joint_r" type="revolute">
        <origin rpy="0 1.57079637 0" xyz="0.131 0.06 -0.008" />
        <parent link="link_u" />
        <child link="link_r" />
        <axis xyz="0 0 -1" />
        <dynamics damping="0.7" friction="0.7" />
        <limit effort="14.7" lower="-2.98451293719" upper="2.98451293719" velocity="3.31612567" />
    </joint>
    <joint name="joint_b" type="revolute">
        <origin rpy="0 -1.57079637 0" xyz="-0.0045 0 0.139" />
        <parent link="link_r" />
        <child link="link_b" />
        <axis xyz="0 0 1" />
        <dynamics damping="0.7" friction="0.7" />
        <limit effort="14.7" lower="-1.8238691185" upper="1.8238691185" velocity="3.8135445205" />
    </joint>
    <joint name="joint_t" type="revolute">
        <origin rpy="-1.57079637 0 0" xyz="0.1365 0 -0.0045" />
        <parent link="link_b" />
        <child link="link_t" />
        <axis xyz="-1 0 0" />
        <dynamics damping="0.7" friction="0.7" />
        <limit effort="7.35" lower="-2.98451293719" upper="2.98451293719" velocity="5.8032199225" />
    </joint>
    <joint name="joint_tool0" type="fixed">
        <origin rpy="0 0 0" xyz="0.0115 0 0" />
        <!-- <origin rpy="0 0 0" xyz="0.34 0 0"/> -->
        <parent link="link_t" />
        <child link="tool0" />
    </joint>
    <transmission name="transmission_s">
        <type>transmission_interface/SimpleTransmission</type>
        <joint name="joint_s">
            <hardwareInterface>PositionJointInterface</hardwareInterface>
        </joint>
        <actuator name="motor_s">
            <hardwareInterface>PositionJointInterface</hardwareInterface>
            <mechanicalReduction>300</mechanicalReduction>
        </actuator>
    </transmission>
    <transmission name="transmission_l">
        <type>transmission_interface/SimpleTransmission</type>
        <joint name="joint_l">
            <hardwareInterface>PositionJointInterface</hardwareInterface>
        </joint>
        <actuator name="motor_l">
            <hardwareInterface>PositionJointInterface</hardwareInterface>
            <mechanicalReduction>300</mechanicalReduction>
        </actuator>
    </transmission>
    <transmission name="transmission_e">
        <type>transmission_interface/SimpleTransmission</type>
        <joint name="joint_e">
            <hardwareInterface>PositionJointInterface</hardwareInterface>
        </joint>
        <actuator name="motor_e">
            <hardwareInterface>PositionJointInterface</hardwareInterface>
            <mechanicalReduction>100</mechanicalReduction>
        </actuator>
    </transmission>
    <transmission name="transmission_u">
        <type>transmission_interface/SimpleTransmission</type>
        <joint name="joint_u">
            <hardwareInterface>PositionJointInterface</hardwareInterface>
        </joint>
        <actuator name="motor_u">
            <hardwareInterface>PositionJointInterface</hardwareInterface>
            <mechanicalReduction>50</mechanicalReduction>
        </actuator>
    </transmission>
    <transmission name="transmission_r">
        <type>transmission_interface/SimpleTransmission</type>
        <joint name="joint_r">
            <hardwareInterface>PositionJointInterface</hardwareInterface>
        </joint>
        <actuator name="motor_r">
            <hardwareInterface>PositionJointInterface</hardwareInterface>
            <mechanicalReduction>30</mechanicalReduction>
        </actuator>
    </transmission>
    <transmission name="transmission_b">
        <type>transmission_interface/SimpleTransmission</type>
        <joint name="joint_b">
            <hardwareInterface>PositionJointInterface</hardwareInterface>
        </joint>
        <actuator name="motor_b">
            <hardwareInterface>PositionJointInterface</hardwareInterface>
            <mechanicalReduction>30</mechanicalReduction>
        </actuator>
    </transmission>
    <transmission name="transmission_t">
        <type>transmission_interface/SimpleTransmission</type>
        <joint name="joint_t">
            <hardwareInterface>PositionJointInterface</hardwareInterface>
        </joint>
        <actuator name="motor_t">
            <hardwareInterface>PositionJointInterface</hardwareInterface>
            <mechanicalReduction>10</mechanicalReduction>
        </actuator>
    </transmission>
    <!-- gazebo -->
    <gazebo>
        <plugin filename="libgazebo_ros_control.so" name="gazebo_ros_control">
            <robotSimType>gazebo_ros_control/DefaultRobotHWSim</robotSimType>
        </plugin>
    </gazebo>
    <gazebo reference="base_link">
        <mu1>0.2</mu1>
        <mu2>0.2</mu2>
        <selfCollide>true</selfCollide>
    </gazebo>
    <gazebo reference="link_s">
        <mu1>0.2</mu1>
        <mu2>0.2</mu2>
        <selfCollide>true</selfCollide>
    </gazebo>
    <gazebo reference="link_l">
        <mu1>0.2</mu1>
        <mu2>0.2</mu2>
        <selfCollide>true</selfCollide>
    </gazebo>
    <gazebo reference="link_e">
        <mu1>0.2</mu1>
        <mu2>0.2</mu2>
        <selfCollide>true</selfCollide>
    </gazebo>
    <gazebo reference="link_u">
        <mu1>0.2</mu1>
        <mu2>0.2</mu2>
        <selfCollide>true</selfCollide>
    </gazebo>
    <gazebo reference="link_r">
        <mu1>0.2</mu1>
        <mu2>0.2</mu2>
        <selfCollide>true</selfCollide>
    </gazebo>
    <gazebo reference="link_b">
        <mu1>0.2</mu1>
        <mu2>0.2</mu2>
        <selfCollide>true</selfCollide>
    </gazebo>
    <gazebo reference="link_t">
        <mu1>0.2</mu1>
        <mu2>0.2</mu2>
        <selfCollide>true</selfCollide>
    </gazebo>
    <link name="00_manifold">
        <visual>
            <origin rpy="-1.57079632679 -1.57079632679 1.57079632679" xyz="0 0 0" />
            <geometry>
                <mesh filename="package://motoman_description/meshes/twintool/20200831/00_Manifold_20200831.stl" scale="0.001 0.001 0.001" />
            </geometry>
        </visual>
        <collision>
            <origin rpy="-1.57079632679 -1.57079632679 1.57079632679" xyz="0 0 0" />
            <geometry>
                <mesh filename="package://motoman_description/meshes/twintool/20200831/00_Manifold_20200831.stl" scale="0.001 0.001 0.001" />
            </geometry>
        </collision>
        
<inertial>
            <mass value="0.1" />
            <inertia ixx="0.03" iyy="0.03" izz="0.03" ixy="0.0" ixz="0.0" iyz="0.0" />
        </inertial>

    </link>
    <joint name="manifold_to_robotiq-fts-300_adapter" type="fixed">
        <parent link="00_manifold" />
        <child link="01_robotiq-fts-300_adapter" />
        <origin xyz="0 0 0.015" />
    </joint>
    <link name="01_robotiq-fts-300_adapter">
        <visual>
            <origin rpy="0.0 0 3.14159265359" xyz="0 0 0" />
            <geometry>
                <mesh filename="package://motoman_description/meshes/twintool/20200831/02_ROBOTIQ_FTS-300_ADAPTER.stl" scale="0.001 0.001 0.001" />
            </geometry>
        </visual>
        <collision>
            <origin rpy="0.0 0 3.14159265359" xyz="0 0 0" />
            <geometry>
                <mesh filename="package://motoman_description/meshes/twintool/20200831/02_ROBOTIQ_FTS-300_ADAPTER.stl" scale="0.001 0.001 0.001" />
            </geometry>
        </collision>
        
<inertial>
            <mass value="0.1" />
            <inertia ixx="0.03" iyy="0.03" izz="0.03" ixy="0.0" ixz="0.0" iyz="0.0" />
        </inertial>

    </link>
    <!-- mount the fts to the robot -->
    <joint name="ft300_fix" type="fixed">
        <origin rpy="0 3.14159265359 3.14159265359" xyz="0 0 0.0535" />
        <parent link="01_robotiq-fts-300_adapter" />
        <!-- <child link="${prefix}ft300_mounting_plate" /> -->
        <child link="ft300_sensor" />
    </joint>
    <!-- Link representing the FT300 force-torque sensor -->
    <link name="ft300_sensor">
        
<inertial>
            <origin rpy="0 0 0" xyz="0 0 -0.017" />
            <mass value="0.300" />
            <inertia ixx="0.000262" ixy="0" ixz="1e-06" iyx="0" iyy="0.000265" iyz="1e-06" izx="-1e-06" izy="1e-06" izz="0.000219" />
        </inertial>

        <visual>
            <origin rpy="0 0 0" xyz="0 0 0" />
            <geometry>
                <mesh filename="package://robotiq_ft_sensor/meshes/visual/robotiq_ft300.STL" />
            </geometry>
            <material name="Robotiq-Black">
                <color rgba="0.2 0.2 0.2 1.0" />
            </material>
        </visual>
        <collision>
            <origin rpy="0 0 0" xyz="0 0 0" />
            <geometry>
                <mesh filename="package://robotiq_ft_sensor/meshes/collision/robotiq_ft300.STL" />
            </geometry>
        </collision>
    </link>
    <joint name="measurment_joint" type="fixed">
        <origin rpy="0 3.14159265359 -1.57079632679" xyz="0 0 0" />
        <parent link="ft300_sensor" />
        <child link="robotiq_ft_frame_id" />
    </joint>
    <link name="robotiq_ft_frame_id" />
    <joint name="robotiq-fts-300_to_mee-base" type="fixed">
        <parent link="ft300_sensor" />
        <child link="03.5_mee-base" />
        <origin rpy="0 3.14159265359 3.14159265359" xyz="0 0 0" />
    </joint>
    <!-- ++++++++++++++++++++++++++++++++++++++++++++++++++++++++++++++++++++++++++++++++++++++++++++++++++++++++++ -->
    <link name="03.5_mee-base">
        <visual>
            <origin rpy="-1.57079632679 -1.57079632679 1.57079632679" xyz="0 0 0" />
            <geometry>
                <mesh filename="package://motoman_description/meshes/twintool/20200831/04_MX106-Assem_20200831.stl" scale="0.001 0.001 0.001" />
            </geometry>
        </visual>
        <collision>
            <origin rpy="-1.57079632679 -1.57079632679 1.57079632679" xyz="0 0 0" />
            <geometry>
                <mesh filename="package://motoman_description/meshes/twintool/20200831/04_MX106-Assem_20200831.stl" scale="0.001 0.001 0.001" />
            </geometry>
        </collision>
        
<inertial>
            <mass value="0.1" />
            <inertia ixx="0.03" iyy="0.03" izz="0.03" ixy="0.0" ixz="0.0" iyz="0.0" />
        </inertial>

    </link>
    <joint name="mee-base_to_rs-d35" type="fixed">
        <parent link="03.5_mee-base" />
        <child link="05_rs-d435" />
        <origin xyz="-0.01750000094 0.067 0.1305" />
    </joint>
    <link name="05_rs-d435">
        <visual>
            <origin rpy="0 0 0" xyz="0 0 0" />
            <geometry>
                <mesh filename="package://realsense2_description/meshes/d435.dae" />
            </geometry>
        </visual>
        <collision>
            <origin rpy="0 0 0" xyz="0 0 0" />
            <geometry>
                <mesh filename="package://realsense2_description/meshes/d435.dae" />
            </geometry>
        </collision>
        
<inertial>
            <mass value="0.1" />
            <inertia ixx="0.03" iyy="0.03" izz="0.03" ixy="0.0" ixz="0.0" iyz="0.0" />
        </inertial>

    </link>
    <joint name="twintool_joint1" type="revolute">
        <axis xyz="0 0 1" />
        <limit effort="1000.0" lower="0.0" upper="3.15" velocity="0.5" />
        <parent link="03.5_mee-base" />
        <child link="dual_gripper_mount" />
        <origin rpy="0.785398163397 0 0" xyz="0 0 0.07750003396" />
    </joint>
    <joint name="mee-base_to_imu_lpms-b2" type="fixed">
        <parent link="03.5_mee-base" />
        <child link="imu_lpms-b2_frame_id" />
        <origin xyz="0 0 0.0425" />
    </joint>
    <link name="imu_lpms-b2_frame_id" />
    <link name="dual_gripper_mount" />
    <joint name="dual_gripper_fix" type="fixed">
        <origin rpy="-0.785398163397 0.0 0" xyz="0 0 0" />
        <parent link="dual_gripper_mount" />
        <child link="06_mee-tool-base" />
    </joint>
    <link name="06_mee-tool-base">
        <visual>
            <origin rpy="0 -1.57079632679 0" xyz="0 0 0" />
            <geometry>
                <mesh filename="package://motoman_description/meshes/twintool/20200831/06_Tool base-Assem_20200831.stl" scale="0.001 0.001 0.001" />
            </geometry>
        </visual>
        <collision>
            <origin rpy="0 -1.57079632679 0" xyz="0 0 0" />
            <geometry>
                <mesh filename="package://motoman_description/meshes/twintool/20200831/06_Tool base-Assem_20200831.stl" scale="0.001 0.001 0.001" />
            </geometry>
        </collision>
        
<inertial>
            <mass value="0.1" />
            <inertia ixx="0.03" iyy="0.03" izz="0.03" ixy="0.0" ixz="0.0" iyz="0.0" />
        </inertial>

    </link>
    <!-- **************************************************************************************************** -->
    <joint name="mee-tool-base_to_vacuum-pad" type="fixed">
        <parent link="06_mee-tool-base" />
        <child link="07-0_vacuum-pad" />
        <origin xyz="0 0 0" />
    </joint>
    <link name="07-0_vacuum-pad">
        <visual>
            <origin rpy="0 -1.57079632679 1.57079632679" xyz="0 0 0.065" />
            <geometry>
                <mesh filename="package://motoman_description/meshes/twintool/20200831/10_Vacuum_20200831.stl" scale="0.001 0.001 0.001" />
            </geometry>
        </visual>
        <collision>
            <origin rpy="0 -1.57079632679 1.57079632679" xyz="0 0 0.065" />
            <geometry>
                <mesh filename="package://motoman_description/meshes/twintool/20200831/10_Vacuum_20200831.stl" scale="0.001 0.001 0.001" />
            </geometry>
        </collision>
        
<inertial>
            <mass value="0.1" />
            <inertia ixx="0.03" iyy="0.03" izz="0.03" ixy="0.0" ixz="0.0" iyz="0.0" />
        </inertial>

    </link>
    <link name="tool0_center_point" />
    <joint name="tool0_center_point_joint" type="fixed">
        <parent link="06_mee-tool-base" />
        <child link="tool0_center_point" />
        <origin rpy="0 0 3.14159265359" xyz="0 0 0.152" />
    </joint>
    <!-- **************************************************************************************************** -->
    <joint name="twintool_joint2_1" type="revolute">
        <axis xyz="-1 0 0" />
        <limit effort="1000.0" lower="0" upper="0.6" velocity="0.5" />
        <parent link="06_mee-tool-base" />
        <child link="07-1-1_soft-robotics-gripper" />
        <origin rpy="0 -1.57079632679 0" xyz="0.0225 -0.08603427086 0" />
    </joint>
    <joint name="twintool_joint2_2" type="revolute">
        <axis xyz="-1 0 0" />
        <limit effort="1000.0" lower="-0.6" upper="0" velocity="0.5" />
        <parent link="06_mee-tool-base" />
        <child link="07-1-2_soft-robotics-gripper" />
        <origin rpy="0 -1.57079632679 0" xyz="-0.0225 -0.08603427086 0" />
        <mimic joint="twintool_joint2_1" multiplier="-1" offset="0" />
    </joint>
    <link name="07-1-1_soft-robotics-gripper">
        <visual>
            <origin rpy="0 0 0" xyz="0 0 0" />
            <geometry>
                <mesh filename="package://motoman_description/meshes/twintool/20200831/08-1_SRDK-R_20200831.stl" scale="0.001 0.001 0.001" />
            </geometry>
        </visual>
        <collision>
            <origin rpy="0 0 0" xyz="0 0 0" />
            <geometry>
                <mesh filename="package://motoman_description/meshes/twintool/20200831/08-1_SRDK-R_20200831.stl" scale="0.001 0.001 0.001" />
            </geometry>
        </collision>
        
<inertial>
            <mass value="0.1" />
            <inertia ixx="0.03" iyy="0.03" izz="0.03" ixy="0.0" ixz="0.0" iyz="0.0" />
        </inertial>

    </link>
    <link name="07-1-2_soft-robotics-gripper">
        <visual>
            <origin rpy="0 0 0" xyz="0 0 0" />
            <geometry>
                <mesh filename="package://motoman_description/meshes/twintool/20200831/08-2_SRDK_20200831.stl" scale="0.001 0.001 0.001" />
            </geometry>
        </visual>
        <collision>
            <origin rpy="0 0 0" xyz="0 0 0" />
            <geometry>
                <mesh filename="package://motoman_description/meshes/twintool/20200831/08-2_SRDK_20200831.stl" scale="0.001 0.001 0.001" />
            </geometry>
        </collision>
        
<inertial>
            <mass value="0.1" />
            <inertia ixx="0.03" iyy="0.03" izz="0.03" ixy="0.0" ixz="0.0" iyz="0.0" />
        </inertial>

    </link>
    <link name="tool1_center_point" />
    <joint name="tool1_center_point_joint" type="fixed">
        <parent link="06_mee-tool-base" />
        <child link="tool1_center_point" />
        <origin rpy="1.57079632679 0  0" xyz="0 -0.15103427086 0" />
    </joint>
    <link name="world" />
    <joint name="world" type="fixed">
        <origin rpy="0 0 0" xyz="0 0 0.2" />
        <parent link="world" />
        <child link="base_link" />
    </joint>
    <!-- Joint -->
    <joint name="tool0_twintool" type="fixed">
        <origin rpy="1.57079637 0 1.57079637" xyz="0 0 0" />
        <parent link="tool0" />
        <child link="00_manifold" />
    </joint>
    <link name="tool_ee_link" />
    <joint name="tool0_ee_joint" type="fixed">
        <origin rpy="0 0 0" xyz="0.325 0 0" />
        <parent link="tool0" />
        <child link="tool_ee_link" />
    </joint>
    <!-- #################### world ################### -->
    <!--   load the model of the motoman base etc-->
    <link name="motoman_base">
        <visual>
            <geometry>
                <mesh filename="package://motoman_description/urdf/sia5/motoman_base.stl" />
            </geometry>
            <origin rpy="1.57079637 0 1.57079637" xyz="0 0 0" />
            <material name="Green">
                <color rgba="0 1 0 0.5" />
            </material>
        </visual>
        <collision>
            <geometry>
                <mesh filename="package://motoman_description/urdf/sia5/motoman_base.stl" />
            </geometry>
            <origin rpy="1.57079637 0 1.57079637" xyz="0 0 0" />
        </collision>
        
<inertial>
            <mass value="0.1" />
            <inertia ixx="0.03" iyy="0.03" izz="0.03" ixy="0.0" ixz="0.0" iyz="0.0" />
        </inertial>

    </link>
    <joint name="motoman_base_to_world" type="fixed">
        <parent link="world" />
        <child link="motoman_base" />
        <origin rpy="0 0 0" xyz="0.55 0.33 -0.5" />
    </joint>
    <!-- <link name="place_box">
    <visual>
      <geometry>
        <mesh filename="package://motoman_description/urdf/sia5/box_motoman.stl"/>
      </geometry>
      <origin xyz="0 0 0" rpy="1.5707 0 0"/>
      <material name="Green">
        <color rgba="0 1 0 0.5"/>
      </material>
    </visual>
    <collision>
      <geometry>
        <mesh filename="package://motoman_description/urdf/sia5/box_motoman.stl"/>
      </geometry>
      <origin xyz="0 0 0" rpy="1.5707 0 0"/>
    </collision>
  </link>

  <joint name="plane_base_to_place_box" type="fixed">
    <parent link="world"/>
    <child link="place_box"/>
    <origin xyz="0.43 -0.210 0.028" rpy="0 0 0"/>
  </joint> -->
    <!-- box with d435i camera-->
    <!-- <link name="place_d435i">
    <visual>
      <geometry>
        <box size="0.125 0.34 0.34"/>
      </geometry>
      <origin xyz="0 0 0.17" rpy="0 0 0"/>
      <material name="Green">
        <color rgba="0 1 0 0.5"/>
      </material>
    </visual>
    <collision>
      <geometry>
        <box size="0.125 0.34 0.34"/>
      </geometry>
      <origin xyz="0 0 0.17" rpy="0 0 0"/>
    </collision>
  </link>

  <joint name="plane_base_to_place_d435i" type="fixed">
    <parent link="world"/>
    <child link="place_d435i"/>
    <origin xyz="0.14 0 0.028" rpy="0 0 0"/>
  </joint> -->
    <!-- place backplane-->
    <link name="backplane">
        <visual>
            <geometry>
                <box size="0.0001 1.35 1.35" />
            </geometry>
            <origin rpy="0 0 0" xyz="0 0 0.6751" />
            <material name="Red">
                <color rgba="1 0 0 0.1" />
            </material>
        </visual>
        <collision>
            <geometry>
                <box size="0.0001 1.4 1.4" />
            </geometry>
            <origin rpy="0 0 0" xyz="0 0 0.601" />
        </collision>
        
<inertial>
            <mass value="0.1" />
            <inertia ixx="0.03" iyy="0.03" izz="0.03" ixy="0.0" ixz="0.0" iyz="0.0" />
        </inertial>

    </link>
    <joint name="pole1_to_backplane" type="fixed">
        <parent link="world" />
        <child link="backplane" />
        <origin rpy="0 0 0" xyz="-0.40 0 0" />
    </joint>
    <transmission name="trans_joint_s">
        <type>transmission_interface/SimpleTransmission</type>
        <joint name="joint_s">
            <hardwareInterface>hardware_interface/EffortJointInterface</hardwareInterface>
        </joint>
        <actuator name="joint_s_motor">
            <hardwareInterface>hardware_interface/EffortJointInterface</hardwareInterface>
            <mechanicalReduction>1</mechanicalReduction>
        </actuator>
    </transmission>
    <transmission name="trans_joint_l">
        <type>transmission_interface/SimpleTransmission</type>
        <joint name="joint_l">
            <hardwareInterface>hardware_interface/EffortJointInterface</hardwareInterface>
        </joint>
        <actuator name="joint_l_motor">
            <hardwareInterface>hardware_interface/EffortJointInterface</hardwareInterface>
            <mechanicalReduction>1</mechanicalReduction>
        </actuator>
    </transmission>
    <transmission name="trans_joint_e">
        <type>transmission_interface/SimpleTransmission</type>
        <joint name="joint_e">
            <hardwareInterface>hardware_interface/EffortJointInterface</hardwareInterface>
        </joint>
        <actuator name="joint_e_motor">
            <hardwareInterface>hardware_interface/EffortJointInterface</hardwareInterface>
            <mechanicalReduction>1</mechanicalReduction>
        </actuator>
    </transmission>
    <transmission name="trans_joint_u">
        <type>transmission_interface/SimpleTransmission</type>
        <joint name="joint_u">
            <hardwareInterface>hardware_interface/EffortJointInterface</hardwareInterface>
        </joint>
        <actuator name="joint_u_motor">
            <hardwareInterface>hardware_interface/EffortJointInterface</hardwareInterface>
            <mechanicalReduction>1</mechanicalReduction>
        </actuator>
    </transmission>
    <transmission name="trans_joint_r">
        <type>transmission_interface/SimpleTransmission</type>
        <joint name="joint_r">
            <hardwareInterface>hardware_interface/EffortJointInterface</hardwareInterface>
        </joint>
        <actuator name="joint_r_motor">
            <hardwareInterface>hardware_interface/EffortJointInterface</hardwareInterface>
            <mechanicalReduction>1</mechanicalReduction>
        </actuator>
    </transmission>
    <transmission name="trans_joint_b">
        <type>transmission_interface/SimpleTransmission</type>
        <joint name="joint_b">
            <hardwareInterface>hardware_interface/EffortJointInterface</hardwareInterface>
        </joint>
        <actuator name="joint_b_motor">
            <hardwareInterface>hardware_interface/EffortJointInterface</hardwareInterface>
            <mechanicalReduction>1</mechanicalReduction>
        </actuator>
    </transmission>
    <transmission name="trans_joint_t">
        <type>transmission_interface/SimpleTransmission</type>
        <joint name="joint_t">
            <hardwareInterface>hardware_interface/EffortJointInterface</hardwareInterface>
        </joint>
        <actuator name="joint_t_motor">
            <hardwareInterface>hardware_interface/EffortJointInterface</hardwareInterface>
            <mechanicalReduction>1</mechanicalReduction>
        </actuator>
    </transmission>
    <transmission name="trans_twintool_joint1">
        <type>transmission_interface/SimpleTransmission</type>
        <joint name="twintool_joint1">
            <hardwareInterface>hardware_interface/EffortJointInterface</hardwareInterface>
        </joint>
        <actuator name="twintool_joint1_motor">
            <hardwareInterface>hardware_interface/EffortJointInterface</hardwareInterface>
            <mechanicalReduction>1</mechanicalReduction>
        </actuator>
    </transmission>
    <transmission name="trans_twintool_joint2_1">
        <type>transmission_interface/SimpleTransmission</type>
        <joint name="twintool_joint2_1">
            <hardwareInterface>hardware_interface/EffortJointInterface</hardwareInterface>
        </joint>
        <actuator name="twintool_joint2_1_motor">
            <hardwareInterface>hardware_interface/EffortJointInterface</hardwareInterface>
            <mechanicalReduction>1</mechanicalReduction>
        </actuator>
    </transmission>
    <transmission name="trans_twintool_joint2_2">
        <type>transmission_interface/SimpleTransmission</type>
        <joint name="twintool_joint2_2">
            <hardwareInterface>hardware_interface/EffortJointInterface</hardwareInterface>
        </joint>
        <actuator name="twintool_joint2_2_motor">
            <hardwareInterface>hardware_interface/EffortJointInterface</hardwareInterface>
            <mechanicalReduction>1</mechanicalReduction>
        </actuator>
    </transmission>
    <gazebo>
        <plugin name="gazebo_ros_control" filename="libgazebo_ros_control.so">
            <robotNamespace>/</robotNamespace>
        </plugin>
    </gazebo>
</robot>

<transmission name="transmission_s">
        <type>transmission_interface/SimpleTransmission</type>
        <joint name="joint_s">
            <hardwareInterface>PositionJointInterface</hardwareInterface>
        </joint>
        <actuator name="motor_s">
            <hardwareInterface>PositionJointInterface</hardwareInterface>
            <mechanicalReduction>300</mechanicalReduction>
        </actuator>
    </transmission>
    <transmission name="transmission_l">
        <type>transmission_interface/SimpleTransmission</type>
        <joint name="joint_l">
            <hardwareInterface>PositionJointInterface</hardwareInterface>
        </joint>
        <actuator name="motor_l">
            <hardwareInterface>PositionJointInterface</hardwareInterface>
            <mechanicalReduction>300</mechanicalReduction>
        </actuator>
    </transmission>
    <transmission name="transmission_e">
        <type>transmission_interface/SimpleTransmission</type>
        <joint name="joint_e">
            <hardwareInterface>PositionJointInterface</hardwareInterface>
        </joint>
        <actuator name="motor_e">
            <hardwareInterface>PositionJointInterface</hardwareInterface>
            <mechanicalReduction>100</mechanicalReduction>
        </actuator>
    </transmission>
    <transmission name="transmission_u">
        <type>transmission_interface/SimpleTransmission</type>
        <joint name="joint_u">
            <hardwareInterface>PositionJointInterface</hardwareInterface>
        </joint>
        <actuator name="motor_u">
            <hardwareInterface>PositionJointInterface</hardwareInterface>
            <mechanicalReduction>50</mechanicalReduction>
        </actuator>
    </transmission>
    <transmission name="transmission_r">
        <type>transmission_interface/SimpleTransmission</type>
        <joint name="joint_r">
            <hardwareInterface>PositionJointInterface</hardwareInterface>
        </joint>
        <actuator name="motor_r">
            <hardwareInterface>PositionJointInterface</hardwareInterface>
            <mechanicalReduction>30</mechanicalReduction>
        </actuator>
    </transmission>
    <transmission name="transmission_b">
        <type>transmission_interface/SimpleTransmission</type>
        <joint name="joint_b">
            <hardwareInterface>PositionJointInterface</hardwareInterface>
        </joint>
        <actuator name="motor_b">
            <hardwareInterface>PositionJointInterface</hardwareInterface>
            <mechanicalReduction>30</mechanicalReduction>
        </actuator>
    </transmission>
    <transmission name="transmission_t">
        <type>transmission_interface/SimpleTransmission</type>
        <joint name="joint_t">
            <hardwareInterface>PositionJointInterface</hardwareInterface>
        </joint>
        <actuator name="motor_t">
            <hardwareInterface>PositionJointInterface</hardwareInterface>
            <mechanicalReduction>10</mechanicalReduction>
        </actuator>
    </transmission>
    <!-- gazebo -->
    <gazebo>
        <plugin filename="libgazebo_ros_control.so" name="gazebo_ros_control">
            <robotSimType>gazebo_ros_control/DefaultRobotHWSim</robotSimType>
        </plugin>
    </gazebo>
    <gazebo reference="base_link">
        <mu1>0.2</mu1>
        <mu2>0.2</mu2>
        <selfCollide>true</selfCollide>
    </gazebo>
    <gazebo reference="link_s">
        <mu1>0.2</mu1>
        <mu2>0.2</mu2>
        <selfCollide>true</selfCollide>
    </gazebo>
    <gazebo reference="link_l">
        <mu1>0.2</mu1>
        <mu2>0.2</mu2>
        <selfCollide>true</selfCollide>
    </gazebo>
    <gazebo reference="link_e">
        <mu1>0.2</mu1>
        <mu2>0.2</mu2>
        <selfCollide>true</selfCollide>
    </gazebo>
    <gazebo reference="link_u">
        <mu1>0.2</mu1>
        <mu2>0.2</mu2>
        <selfCollide>true</selfCollide>
    </gazebo>
    <gazebo reference="link_r">
        <mu1>0.2</mu1>
        <mu2>0.2</mu2>
        <selfCollide>true</selfCollide>
    </gazebo>
    <gazebo reference="link_b">
        <mu1>0.2</mu1>
        <mu2>0.2</mu2>
        <selfCollide>true</selfCollide>
    </gazebo>
    <gazebo reference="link_t">
        <mu1>0.2</mu1>
        <mu2>0.2</mu2>
        <selfCollide>true</selfCollide>
    </gazebo>
    <link name="00_manifold">
        <visual>
            <origin rpy="-1.57079632679 -1.57079632679 1.57079632679" xyz="0 0 0" />
            <geometry>
                <mesh filename="package://motoman_description/meshes/twintool/20200831/00_Manifold_20200831.stl" scale="0.001 0.001 0.001" />
            </geometry>
        </visual>
        <collision>
            <origin rpy="-1.57079632679 -1.57079632679 1.57079632679" xyz="0 0 0" />
            <geometry>
                <mesh filename="package://motoman_description/meshes/twintool/20200831/00_Manifold_20200831.stl" scale="0.001 0.001 0.001" />
            </geometry>
        </collision>
        <inertial>
            <mass value="0.1" />
            <inertia ixx="0.03" iyy="0.03" izz="0.03" ixy="0.0" ixz="0.0" iyz="0.0" />
        </inertial>
    </link>
    <joint name="manifold_to_robotiq-fts-300_adapter" type="fixed">
        <parent link="00_manifold" />
        <child link="01_robotiq-fts-300_adapter" />
        <origin xyz="0 0 0.015" />
    </joint>
    <link name="01_robotiq-fts-300_adapter">
        <visual>
            <origin rpy="0.0 0 3.14159265359" xyz="0 0 0" />
            <geometry>
                <mesh filename="package://motoman_description/meshes/twintool/20200831/02_ROBOTIQ_FTS-300_ADAPTER.stl" scale="0.001 0.001 0.001" />
            </geometry>
        </visual>
        <collision>
            <origin rpy="0.0 0 3.14159265359" xyz="0 0 0" />
            <geometry>
                <mesh filename="package://motoman_description/meshes/twintool/20200831/02_ROBOTIQ_FTS-300_ADAPTER.stl" scale="0.001 0.001 0.001" />
            </geometry>
        </collision>
        <inertial>
            <mass value="0.1" />
            <inertia ixx="0.03" iyy="0.03" izz="0.03" ixy="0.0" ixz="0.0" iyz="0.0" />
        </inertial>
    </link>
    <!-- mount the fts to the robot -->
    <joint name="ft300_fix" type="fixed">
        <origin rpy="0 3.14159265359 3.14159265359" xyz="0 0 0.0535" />
        <parent link="01_robotiq-fts-300_adapter" />
        <!-- <child link="${prefix}ft300_mounting_plate" /> -->
        <child link="ft300_sensor" />
    </joint>
    <!-- Link representing the FT300 force-torque sensor -->
    <link name="ft300_sensor">
        <inertial>
            <origin rpy="0 0 0" xyz="0 0 -0.017" />
            <mass value="0.300" />
            <inertia ixx="0.000262" ixy="0" ixz="1e-06" iyx="0" iyy="0.000265" iyz="1e-06" izx="-1e-06" izy="1e-06" izz="0.000219" />
        </inertial>
        <visual>
            <origin rpy="0 0 0" xyz="0 0 0" />
            <geometry>
                <mesh filename="package://robotiq_ft_sensor/meshes/visual/robotiq_ft300.STL" />
            </geometry>
            <material name="Robotiq-Black">
                <color rgba="0.2 0.2 0.2 1.0" />
            </material>
        </visual>
        <collision>
            <origin rpy="0 0 0" xyz="0 0 0" />
            <geometry>
                <mesh filename="package://robotiq_ft_sensor/meshes/collision/robotiq_ft300.STL" />
            </geometry>
        </collision>
    </link>
    <joint name="measurment_joint" type="fixed">
        <origin rpy="0 3.14159265359 -1.57079632679" xyz="0 0 0" />
        <parent link="ft300_sensor" />
        <child link="robotiq_ft_frame_id" />
    </joint>
    <link name="robotiq_ft_frame_id" />
    <joint name="robotiq-fts-300_to_mee-base" type="fixed">
        <parent link="ft300_sensor" />
        <child link="03.5_mee-base" />
        <origin rpy="0 3.14159265359 3.14159265359" xyz="0 0 0" />
    </joint>
    <!-- ++++++++++++++++++++++++++++++++++++++++++++++++++++++++++++++++++++++++++++++++++++++++++++++++++++++++++ -->
    <link name="03.5_mee-base">
        <visual>
            <origin rpy="-1.57079632679 -1.57079632679 1.57079632679" xyz="0 0 0" />
            <geometry>
                <mesh filename="package://motoman_description/meshes/twintool/20200831/04_MX106-Assem_20200831.stl" scale="0.001 0.001 0.001" />
            </geometry>
        </visual>
        <collision>
            <origin rpy="-1.57079632679 -1.57079632679 1.57079632679" xyz="0 0 0" />
            <geometry>
                <mesh filename="package://motoman_description/meshes/twintool/20200831/04_MX106-Assem_20200831.stl" scale="0.001 0.001 0.001" />
            </geometry>
        </collision>
        <inertial>
            <mass value="0.1" />
            <inertia ixx="0.03" iyy="0.03" izz="0.03" ixy="0.0" ixz="0.0" iyz="0.0" />
        </inertial>
    </link>
    <joint name="mee-base_to_rs-d35" type="fixed">
        <parent link="03.5_mee-base" />
        <child link="05_rs-d435" />
        <origin xyz="-0.01750000094 0.067 0.1305" />
    </joint>
    <link name="05_rs-d435">
        <visual>
            <origin rpy="0 0 0" xyz="0 0 0" />
            <geometry>
                <mesh filename="package://realsense2_description/meshes/d435.dae" />
            </geometry>
        </visual>
        <collision>
            <origin rpy="0 0 0" xyz="0 0 0" />
            <geometry>
                <mesh filename="package://realsense2_description/meshes/d435.dae" />
            </geometry>
        </collision>
        <inertial>
            <mass value="0.1" />
            <inertia ixx="0.03" iyy="0.03" izz="0.03" ixy="0.0" ixz="0.0" iyz="0.0" />
        </inertial>
    </link>
    <joint name="twintool_joint1" type="revolute">
        <axis xyz="0 0 1" />
        <limit effort="1000.0" lower="0.0" upper="3.15" velocity="0.5" />
        <parent link="03.5_mee-base" />
        <child link="dual_gripper_mount" />
        <origin rpy="0.785398163397 0 0" xyz="0 0 0.07750003396" />
    </joint>
    <joint name="mee-base_to_imu_lpms-b2" type="fixed">
        <parent link="03.5_mee-base" />
        <child link="imu_lpms-b2_frame_id" />
        <origin xyz="0 0 0.0425" />
    </joint>
    <link name="imu_lpms-b2_frame_id" />
    <link name="dual_gripper_mount" />
    <joint name="dual_gripper_fix" type="fixed">
        <origin rpy="-0.785398163397 0.0 0" xyz="0 0 0" />
        <parent link="dual_gripper_mount" />
        <child link="06_mee-tool-base" />
    </joint>
    <link name="06_mee-tool-base">
        <visual>
            <origin rpy="0 -1.57079632679 0" xyz="0 0 0" />
            <geometry>
                <mesh filename="package://motoman_description/meshes/twintool/20200831/06_Tool base-Assem_20200831.stl" scale="0.001 0.001 0.001" />
            </geometry>
        </visual>
        <collision>
            <origin rpy="0 -1.57079632679 0" xyz="0 0 0" />
            <geometry>
                <mesh filename="package://motoman_description/meshes/twintool/20200831/06_Tool base-Assem_20200831.stl" scale="0.001 0.001 0.001" />
            </geometry>
        </collision>
        <inertial>
            <mass value="0.1" />
            <inertia ixx="0.03" iyy="0.03" izz="0.03" ixy="0.0" ixz="0.0" iyz="0.0" />
        </inertial>
    </link>
    <!-- **************************************************************************************************** -->
    <joint name="mee-tool-base_to_vacuum-pad" type="fixed">
        <parent link="06_mee-tool-base" />
        <child link="07-0_vacuum-pad" />
        <origin xyz="0 0 0" />
    </joint>
    <link name="07-0_vacuum-pad">
        <visual>
            <origin rpy="0 -1.57079632679 1.57079632679" xyz="0 0 0.065" />
            <geometry>
                <mesh filename="package://motoman_description/meshes/twintool/20200831/10_Vacuum_20200831.stl" scale="0.001 0.001 0.001" />
            </geometry>
        </visual>
        <collision>
            <origin rpy="0 -1.57079632679 1.57079632679" xyz="0 0 0.065" />
            <geometry>
                <mesh filename="package://motoman_description/meshes/twintool/20200831/10_Vacuum_20200831.stl" scale="0.001 0.001 0.001" />
            </geometry>
        </collision>
        <inertial>
            <mass value="0.1" />
            <inertia ixx="0.03" iyy="0.03" izz="0.03" ixy="0.0" ixz="0.0" iyz="0.0" />
        </inertial>
    </link>
    <link name="tool0_center_point" />
    <joint name="tool0_center_point_joint" type="fixed">
        <parent link="06_mee-tool-base" />
        <child link="tool0_center_point" />
        <origin rpy="0 0 3.14159265359" xyz="0 0 0.152" />
    </joint>
    <!-- **************************************************************************************************** -->
    <joint name="twintool_joint2_1" type="revolute">
        <axis xyz="-1 0 0" />
        <limit effort="1000.0" lower="0" upper="0.6" velocity="0.5" />
        <parent link="06_mee-tool-base" />
        <child link="07-1-1_soft-robotics-gripper" />
        <origin rpy="0 -1.57079632679 0" xyz="0.0225 -0.08603427086 0" />
    </joint>
    <joint name="twintool_joint2_2" type="revolute">
        <axis xyz="-1 0 0" />
        <limit effort="1000.0" lower="-0.6" upper="0" velocity="0.5" />
        <parent link="06_mee-tool-base" />
        <child link="07-1-2_soft-robotics-gripper" />
        <origin rpy="0 -1.57079632679 0" xyz="-0.0225 -0.08603427086 0" />
        <mimic joint="twintool_joint2_1" multiplier="-1" offset="0" />
    </joint>
    <link name="07-1-1_soft-robotics-gripper">
        <visual>
            <origin rpy="0 0 0" xyz="0 0 0" />
            <geometry>
                <mesh filename="package://motoman_description/meshes/twintool/20200831/08-1_SRDK-R_20200831.stl" scale="0.001 0.001 0.001" />
            </geometry>
        </visual>
        <collision>
            <origin rpy="0 0 0" xyz="0 0 0" />
            <geometry>
                <mesh filename="package://motoman_description/meshes/twintool/20200831/08-1_SRDK-R_20200831.stl" scale="0.001 0.001 0.001" />
            </geometry>
        </collision>
        <inertial>
            <mass value="0.1" />
            <inertia ixx="0.03" iyy="0.03" izz="0.03" ixy="0.0" ixz="0.0" iyz="0.0" />
        </inertial>
    </link>
    <link name="07-1-2_soft-robotics-gripper">
        <visual>
            <origin rpy="0 0 0" xyz="0 0 0" />
            <geometry>
                <mesh filename="package://motoman_description/meshes/twintool/20200831/08-2_SRDK_20200831.stl" scale="0.001 0.001 0.001" />
            </geometry>
        </visual>
        <collision>
            <origin rpy="0 0 0" xyz="0 0 0" />
            <geometry>
                <mesh filename="package://motoman_description/meshes/twintool/20200831/08-2_SRDK_20200831.stl" scale="0.001 0.001 0.001" />
            </geometry>
        </collision>
        <inertial>
            <mass value="0.1" />
            <inertia ixx="0.03" iyy="0.03" izz="0.03" ixy="0.0" ixz="0.0" iyz="0.0" />
        </inertial>
    </link>
    <link name="tool1_center_point" />
    <joint name="tool1_center_point_joint" type="fixed">
        <parent link="06_mee-tool-base" />
        <child link="tool1_center_point" />
        <origin rpy="1.57079632679 0  0" xyz="0 -0.15103427086 0" />
    </joint>
    <link name="world" />
    <joint name="world" type="fixed">
        <origin rpy="0 0 0" xyz="0 0 0.2" />
        <parent link="world" />
        <child link="base_link" />
    </joint>
    <!-- Joint -->
    <joint name="tool0_twintool" type="fixed">
        <origin rpy="1.57079637 0 1.57079637" xyz="0 0 0" />
        <parent link="tool0" />
        <child link="00_manifold" />
    </joint>
    <link name="tool_ee_link" />
    <joint name="tool0_ee_joint" type="fixed">
        <origin rpy="0 0 0" xyz="0.325 0 0" />
        <parent link="tool0" />
        <child link="tool_ee_link" />
    </joint>
    <!-- #################### world ################### -->
    <!--   load the model of the motoman base etc-->
    <link name="motoman_base">
        <visual>
            <geometry>
                <mesh filename="package://motoman_description/urdf/sia5/motoman_base.stl" />
            </geometry>
            <origin rpy="1.57079637 0 1.57079637" xyz="0 0 0" />
            <material name="Green">
                <color rgba="0 1 0 0.5" />
            </material>
        </visual>
        <collision>
            <geometry>
                <mesh filename="package://motoman_description/urdf/sia5/motoman_base.stl" />
            </geometry>
            <origin rpy="1.57079637 0 1.57079637" xyz="0 0 0" />
        </collision>
        <inertial>
            <mass value="0.1" />
            <inertia ixx="0.03" iyy="0.03" izz="0.03" ixy="0.0" ixz="0.0" iyz="0.0" />
        </inertial>
    </link>
    <joint name="motoman_base_to_world" type="fixed">
        <parent link="world" />
        <child link="motoman_base" />
        <origin rpy="0 0 0" xyz="0.55 0.33 -0.5" />
    </joint>
    <!-- <link name="place_box">
    <visual>
      <geometry>
        <mesh filename="package://motoman_description/urdf/sia5/box_motoman.stl"/>
      </geometry>
      <origin xyz="0 0 0" rpy="1.5707 0 0"/>
      <material name="Green">
        <color rgba="0 1 0 0.5"/>
      </material>
    </visual>
    <collision>
      <geometry>
        <mesh filename="package://motoman_description/urdf/sia5/box_motoman.stl"/>
      </geometry>
      <origin xyz="0 0 0" rpy="1.5707 0 0"/>
    </collision>
  </link>

  <joint name="plane_base_to_place_box" type="fixed">
    <parent link="world"/>
    <child link="place_box"/>
    <origin xyz="0.43 -0.210 0.028" rpy="0 0 0"/>
  </joint> -->
    <!-- box with d435i camera-->
    <!-- <link name="place_d435i">
    <visual>
      <geometry>
        <box size="0.125 0.34 0.34"/>
      </geometry>
      <origin xyz="0 0 0.17" rpy="0 0 0"/>
      <material name="Green">
        <color rgba="0 1 0 0.5"/>
      </material>
    </visual>
    <collision>
      <geometry>
        <box size="0.125 0.34 0.34"/>
      </geometry>
      <origin xyz="0 0 0.17" rpy="0 0 0"/>
    </collision>
  </link>

  <joint name="plane_base_to_place_d435i" type="fixed">
    <parent link="world"/>
    <child link="place_d435i"/>
    <origin xyz="0.14 0 0.028" rpy="0 0 0"/>
  </joint> -->
    <!-- place backplane-->
    <link name="backplane">
        <visual>
            <geometry>
                <box size="0.0001 1.35 1.35" />
            </geometry>
            <origin rpy="0 0 0" xyz="0 0 0.6751" />
            <material name="Red">
                <color rgba="1 0 0 0.1" />
            </material>
        </visual>
        <collision>
            <geometry>
                <box size="0.0001 1.4 1.4" />
            </geometry>
            <origin rpy="0 0 0" xyz="0 0 0.601" />
        </collision>
        <inertial>
            <mass value="0.1" />
            <inertia ixx="0.03" iyy="0.03" izz="0.03" ixy="0.0" ixz="0.0" iyz="0.0" />
        </inertial>
    </link>
    <joint name="pole1_to_backplane" type="fixed">
        <parent link="world" />
        <child link="backplane" />
        <origin rpy="0 0 0" xyz="-0.40 0 0" />
    </joint>
    <transmission name="trans_joint_s">
        <type>transmission_interface/SimpleTransmission</type>
        <joint name="joint_s">
            <hardwareInterface>hardware_interface/EffortJointInterface</hardwareInterface>
        </joint>
        <actuator name="joint_s_motor">
            <hardwareInterface>hardware_interface/EffortJointInterface</hardwareInterface>
            <mechanicalReduction>1</mechanicalReduction>
        </actuator>
    </transmission>
    <transmission name="trans_joint_l">
        <type>transmission_interface/SimpleTransmission</type>
        <joint name="joint_l">
            <hardwareInterface>hardware_interface/EffortJointInterface</hardwareInterface>
        </joint>
        <actuator name="joint_l_motor">
            <hardwareInterface>hardware_interface/EffortJointInterface</hardwareInterface>
            <mechanicalReduction>1</mechanicalReduction>
        </actuator>
    </transmission>
    <transmission name="trans_joint_e">
        <type>transmission_interface/SimpleTransmission</type>
        <joint name="joint_e">
            <hardwareInterface>hardware_interface/EffortJointInterface</hardwareInterface>
        </joint>
        <actuator name="joint_e_motor">
            <hardwareInterface>hardware_interface/EffortJointInterface</hardwareInterface>
            <mechanicalReduction>1</mechanicalReduction>
        </actuator>
    </transmission>
    <transmission name="trans_joint_u">
        <type>transmission_interface/SimpleTransmission</type>
        <joint name="joint_u">
            <hardwareInterface>hardware_interface/EffortJointInterface</hardwareInterface>
        </joint>
        <actuator name="joint_u_motor">
            <hardwareInterface>hardware_interface/EffortJointInterface</hardwareInterface>
            <mechanicalReduction>1</mechanicalReduction>
        </actuator>
    </transmission>
    <transmission name="trans_joint_r">
        <type>transmission_interface/SimpleTransmission</type>
        <joint name="joint_r">
            <hardwareInterface>hardware_interface/EffortJointInterface</hardwareInterface>
        </joint>
        <actuator name="joint_r_motor">
            <hardwareInterface>hardware_interface/EffortJointInterface</hardwareInterface>
            <mechanicalReduction>1</mechanicalReduction>
        </actuator>
    </transmission>
    <transmission name="trans_joint_b">
        <type>transmission_interface/SimpleTransmission</type>
        <joint name="joint_b">
            <hardwareInterface>hardware_interface/EffortJointInterface</hardwareInterface>
        </joint>
        <actuator name="joint_b_motor">
            <hardwareInterface>hardware_interface/EffortJointInterface</hardwareInterface>
            <mechanicalReduction>1</mechanicalReduction>
        </actuator>
    </transmission>
    <transmission name="trans_joint_t">
        <type>transmission_interface/SimpleTransmission</type>
        <joint name="joint_t">
            <hardwareInterface>hardware_interface/EffortJointInterface</hardwareInterface>
        </joint>
        <actuator name="joint_t_motor">
            <hardwareInterface>hardware_interface/EffortJointInterface</hardwareInterface>
            <mechanicalReduction>1</mechanicalReduction>
        </actuator>
    </transmission>
    <transmission name="trans_twintool_joint1">
        <type>transmission_interface/SimpleTransmission</type>
        <joint name="twintool_joint1">
            <hardwareInterface>hardware_interface/EffortJointInterface</hardwareInterface>
        </joint>
        <actuator name="twintool_joint1_motor">
            <hardwareInterface>hardware_interface/EffortJointInterface</hardwareInterface>
            <mechanicalReduction>1</mechanicalReduction>
        </actuator>
    </transmission>
    <transmission name="trans_twintool_joint2_1">
        <type>transmission_interface/SimpleTransmission</type>
        <joint name="twintool_joint2_1">
            <hardwareInterface>hardware_interface/EffortJointInterface</hardwareInterface>
        </joint>
        <actuator name="twintool_joint2_1_motor">
            <hardwareInterface>hardware_interface/EffortJointInterface</hardwareInterface>
            <mechanicalReduction>1</mechanicalReduction>
        </actuator>
    </transmission>
    <transmission name="trans_twintool_joint2_2">
        <type>transmission_interface/SimpleTransmission</type>
        <joint name="twintool_joint2_2">
            <hardwareInterface>hardware_interface/EffortJointInterface</hardwareInterface>
        </joint>
        <actuator name="twintool_joint2_2_motor">
            <hardwareInterface>hardware_interface/EffortJointInterface</hardwareInterface>
            <mechanicalReduction>1</mechanicalReduction>
        </actuator>
    </transmission>
    <gazebo>
        <plugin name="gazebo_ros_control" filename="libgazebo_ros_control.so">
            <robotNamespace>/</robotNamespace>
        </plugin>
    </gazebo>
</robot>